Workbook
Name PRECIO: TOTAL!$F$3
Name PRECIO: PERT!$I$2

Sheet PERT
B2: Componente | C2: Nombre | D2: Descripción | E2: Opensource? | F2: Referencias costo ($CLP) | G2: Referentes (link) | P2: Número | Q2: Intervalos propuestos | R2: sueldos dentro de los intervalos
B3: Pasarela Pago | C3: Stripe | D3: Plataforma de pagos internacional con API robusta y fácil integración | E3: FALSE | F3: 2,9% + $0,30 USD por transacción | G3: https://stripe.com/es-us/pricing | P3: 1 | R3: 1904193
C4: MercadoPago | D4: Plataforma de pagos líder en Latinoamérica con soporte en Chile | E4: FALSE | F4: 2,99% por transacción aprobada | G4: https://www.mercadopago.cl/costs-section/introduction | P4: 2 | R4: 2.500.000, 2.683.899, 2.800.000
C5: Transbank | D5: Pasarela de pagos chilena oficial, acepta débito y crédito local | E5: FALSE | F5: Comisión según contrato comercial | G5: https://www.transbank.cl/soluciones-para-tu-negocio/webpay | P5: 3 | R5: 3.500.000, 3.800.000
E6: FALSE | P6: 4 | R6: 4.500.000, 4.500.000, 4.700.000, 4.700.000
E7: FALSE | P7: 5 | R7: 5500000
E8: FALSE | P8: 6 | R8: 6113916
E9: FALSE
E10: FALSE
E11: FALSE | P11: Sueldo Moda: | Q11: 4600000
E12: FALSE | P12: Pert_Sueldo | Q12: =(F13+F5+(Q11*4))/6 -> #VALUE!
E13: FALSE
E14: FALSE
B17: Componente | C17: Nombre | D17: Descripción | E17: Es opensource? | F17: Referencias costo ($CLP) | G17: Referentes (link) | P17: Número | Q17: Intervalos propuestos | R17: sueldos dentro de los intervalos
B18: Base de datos | C18: SQLite | D18: Base de datos liviana embebida en la app, sin servidor | E18: TRUE | F18: Gratuito | G18: https://www.sqlite.org | P18: 1 | Q18: 1.600.000 – 2.000.000 | R18: 1.608.081, 1.723.763, 1.750.000, 1.789.059
C19: PostgreSQL | D19: Base de datos relacional robusta y escalable | E19: TRUE | F19: Gratuito | G19: https://www.postgresql.org | P19: 2 | Q19: 2.000.001 – 2.400.000 | R19: 2.012.918, 2.060.000, 2.250.000, 2.294.282, 2.400.000
C20: Supabase | D20: Plataforma BaaS con PostgreSQL gestionado en la nube | E20: TRUE | F20: Gratuito hasta 500MB, luego desde $25 USD/mes | G20: https://supabase.com/pricing | P20: 3 | Q20: 2.400.001 – 2.800.000 | R20: -
C21: Railway | D21: Plataforma de hosting con soporte para PostgreSQL | E21: FALSE | F21: Gratuito hasta 5GB, luego desde $5 USD/mes | G21: https://railway.app/pricing | P21: 4 | Q21: 2.800.001 – 3.200.000 | R21: 2.803.663, 3.108.805
C22: Render | D22: Hosting con base de datos PostgreSQL gestionada | E22: FALSE | F22: Gratuito con límites, luego desde $7 USD/mes | G22: https://render.com/pricing | P22: 5 | Q22: 3.200.001 – 3.700.000 | R22: 3690000
C23: AWS RDS | D23: Servicio de base de datos relacional en la nube de Amazon | E23: FALSE | F23: Desde ~$15 USD/mes (~$14.000 CLP) | G23: https://aws.amazon.com/es/rds/pricing
E24: FALSE | P24: Sueldo Moda: | Q24: =(T24+S24)/2 -> 2206459 | S24: 2012918 | T24: 2400000
E25: FALSE | P25: Pert_Sueldo | Q25: =(F19+F25+(Q24*4))/6 -> #VALUE!
E26: FALSE
E27: FALSE
E28: FALSE
E29: FALSE
B32: Componente | C32: Nombre | D32: Descripción | E32: Es opensource? | F32: Referencias costo ($CLP) | G32: Referentes (link) | P32: Número | Q32: Intervalos propuestos | R32: costos dentro de los intervalos
B33: SDK | C33: firebase Auth | D33: Servicio de autenticación de Google con email, SMS y OAuth | E33: FALSE | F33: Gratuito hasta 50K MAUs | G33: https://firebase.google.com/pricing | P33: 1 | Q33: 10.000 – 29.999 | R33: 11.985, 20.225, 26.200
C34: superabase Auth | D34: Autenticación integrada con PostgreSQL, email, SMS y OAuth | E34: TRUE | F34: Gratuito hasta 50K MAUs | G34: https://supabase.com/pricing | P34: 2 | Q34: 30.000 – 49.999 | R34: 44.200, 49.990
C35: Auth0 | D35: Plataforma especializada en autenticación con UI incluida | E35: FALSE | F35: Gratuito hasta 25K MAUs | G35: https://auth0.com/pricing | P35: 3 | Q35: 50.000 – 69.999 | R35: 63.990, 69.990
C36: Clerk | D36: SDK moderno de autenticación con interfaz lista para usar | E36: FALSE | F36: Gratuito hasta 10K MAUs | G36: https://clerk.com/pricing | P36: 4 | Q36: 70.000 – 89.999 | R36: 80.990, 80.990, 82.837, 85.990
C37: Django Allauth | D37: Librería nativa de autenticación para Django | E37: TRUE | F37: 100% gratuito | G37: https://docs.allauth.org | P37: 5 | Q37: 90.000 – 110.000 | R37: 109735
C38: Keycloak | D38: Solución enterprise de autenticación self-hosted | E38: TRUE | F38: 100% gratuito | G38: https://www.keycloak.org
E39: FALSE | P39: Costo_Moda: | Q39: =(T39+S39)/2 -> 83490 | S39: 80990 | T39: 85990
E40: FALSE | P40: Pert_Costo | Q40: =(F34+F43+(Q39*4))/6 -> #VALUE!
E41: FALSE
E42: FALSE
E43: FALSE
E44: FALSE
B47: Componente | C47: Nombre | D47: Descripción | E47: Es opensource? | F47: Referencias costo ($CLP) | G47: Referentes (link)
...

Sheet REMUNERACIONES
A1: REMUNERACIONES, HONORARIOS E INCENTIVOS | G1: =G13/PRECIO -> #VALUE!
A3: ITEM | B3: HONORARIOS | C3: SUELDO MENSUAL $ / MES | D3: SUBTOTAL | E3: DEDICACION AL PROYECTO % JORNADA | F3: # MESES A CONTRATAR | G3: TOTAL PROYECTO $
A4: Profesionales
A5: Gerente de Proyecto | C5: =PERT!Q25 -> #VALUE! | D5: =SUM(B5:C5) -> #VALUE! | E5: 0.2 | F5: 6 | G5: =IF(REMUNERACIONES!$B5<>0,REMUNERACIONES!$D5,D5*E5*F5) -> #VALUE! | H5: =IF(AND(B5>0,C5>0),"*** ERROR ***","") -> #VALUE!
A6: Especialista en IA | C6: =PERT!Q12 -> #VALUE! | D6: =SUM(B6:C6) -> #VALUE! | E6: 0.2 | F6: 1 | G6: =IF(REMUNERACIONES!$B6<>0,REMUNERACIONES!$D6,D6*E6*F6) -> #VALUE! | H6: =IF(AND(B6>0,C6>0),"*** ERROR ***","") -> #VALUE!
A7: Ingeniero en Infraestructura | B7: 800000 | D7: =SUM(B7:C7) -> 800000 | G7: =IF(REMUNERACIONES!$B7<>0,REMUNERACIONES!$D7,D7*E7*F7) -> 800000
A8: Técnicos | G8: =IF(REMUNERACIONES!$B8<>0,REMUNERACIONES!$D8,D8*E8*F8) -> 0 | H8: =IF(AND(B8>0,C8>0),"*** ERROR ***","")
A9: Líder de Desarrollo | C9: 1500000 | D9: =SUM(B9:C9) -> 1500000 | E9: 0.5 | F9: 4 | G9: =IF(REMUNERACIONES!$B9<>0,REMUNERACIONES!$D9,D9*E9*F9) -> 3000000
A10: Desarrollador Backend | C10: 1200000 | D10: =SUM(B10:C10) -> 1200000 | E10: 0.5 | F10: 4 | G10: =IF(REMUNERACIONES!$B10<>0,REMUNERACIONES!$D10,D10*E10*F10) -> 2400000
A11: Desarrollador Frontend / Mobile | C11: 1000000 | D11: =SUM(B11:C11) -> 1000000 | E11: 0.5 | F11: 4 | G11: =IF(REMUNERACIONES!$B11<>0,REMUNERACIONES!$D11,D11*E11*F11) -> 2000000
A12: Analista QA | C12: 1200000 | D12: =SUM(B12:C12) -> 1200000 | E12: 0.5 | F12: 3 | G12: =IF(REMUNERACIONES!$B12<>0,REMUNERACIONES!$D12,D12*E12*F12) -> 1800000 | H12: =IF(AND(B12>0,C12>0),"*** ERROR ***","")
A13: SUBTOTAL | G13: =SUM(G4:G12) -> #VALUE!

Sheet EQUIPOS E INFRAESTRUCTURA
A1: EQUIPOS (Hardware) | F1: ='EQUIPOS E INFRAESTRUCTURA'!$F$9/PRECIO -> #REF!
A3: NOMBRE DEL EQUIPO | B3: DESCRIPCIÓN | C3: COMPRA COSTO UNITARIO $ / UNIDAD | D3: ARRIENDO COSTO UNITARIO $ / MESES | E3: # UNIDADES O MESES | F3: TOTAL $
A4: COMPUTADOR | B4: Equipos para desarrollo y pruebas | C4: =#REF! -> #REF! | E4: 3 | F4: =(C4+D4)*E4 -> #REF!
A5: Impresora térmica | B5: Impresión de comprobantes y tickets | C5: 59990 | E5: 3 | F5: =(+C5+D5)*E5 -> 179970
A6: Lector de huella | B6: Captura biométrica | C6: =PERT!Q40 -> #VALUE! | E6: 3 | F6: =(+C6+D6)*E6 -> #VALUE!
A7: Cámara de seguridad | B7: Captura vehicular y monitoreo | C7: 120000 | E7: 2 | F7: =(+C7+D7)*E7 -> 240000
A8: Lector QR | B8: Validación de pagos y accesos | C8: 50000 | E8: 3 | F8: =(+C8+D8)*E8 -> 150000
A9: SUBTOTAL | F9: =SUBTOTAL(109,'EQUIPOS E INFRAESTRUCTURA'!$F$4:$F$8) -> #REF!
A13: INFRAESTRUCTURA (Instalaciones y Oficinas) | F13: =F18/PRECIO -> #REF!
A15: NOMBRE DE LA INFRAESTRUCTURA | B15: DESCRIPCIÓN | C15: COMPRA COSTO UNITARIO $ / UNIDAD | D15: ARRIENDO COSTO UNITARIO $ / MESES | E15: # UNIDADES O MESES | F15: TOTAL $
A16: UPS respaldo eléctrico | B16: Respaldo energético para continuidad operativa | C16: =#REF! -> #REF! | E16: 1 | F16: =(+C16+D16)*E16 -> #REF!
A17: Oficina de desarrollo | B17: Espacio de trabajo para equipo de desarrollo y coordinación | D17: 300000 | E17: 4 | F17: =(+C17+D17)*E17 -> 1200000
A18: SUBTOTAL | F18: =SUM(F16:F17) -> #REF!

Sheet SOFTWARE Y FUNGIBLES
A1: SOFTWARE (Licencias y SaaS) | D1: =E7/PRECIO -> #REF!
A2: DESCRIPCIÓN | B2: COSTO UNITARIO $ / UNIDAD | C2: CANTIDAD | D2: # MESES | E2: COSTO TOTAL M$
A3: Google Cloud Platform | B3: =#REF! -> #REF! | C3: 1 | D3: 4 | E3: =B3*C3*D3 -> #REF!
A4: Dominio web y DNS | B4: =25000/12 -> 2083.3333 | C4: 1 | D4: 4 | E4: =B4*C4*D4 -> 8333.3333
A5: GitHub Team | B5: 8000 | C5: 3 | D5: 4 | E5: =B5*C5*D5 -> 96000
A6: Figma Professional | B6: 15000 | C6: 1 | D6: 4 | E6: =B6*C6*D6 -> 60000
A7: SUBTOTAL | E7: =SUM(E3:E6) -> #REF!
A10: FUNGIBLES (Productos Consumibles) | D10: =D14/PRECIO -> 0.0032671193
A11: DESCRIPCIÓN | B11: COSTO UNITARIO M$ / UNIDAD | C11: CANTIDAD | D11: COSTO TOTAL M$
A12: Cableado y conectores | B12: 40000 | C12: 1 | D12: =+B12*C12 -> 40000
A13: Pack De 100 Tarjetas Rfid | B13: 60000 | C13: 1 | D13: =+B13*C13 -> 60000
A14: SUBTOTAL | D14: =SUM(D12:D13) -> 100000

Sheet OTROS
A2: GASTOS COMUNES
A3: DESCRIPCIÓN | B3: COSTO UNITARIO $ / UNIDAD | C3: CANTIDAD | D3: COSTO TOTAL $
A4: Luz | B4: 50000 | C4: 4 | D4: =B4*C4 -> 200000
A5: Agua | B5: 35000 | C5: 4 | D5: =B5*C5 -> 140000
A6: Internet | B6: 45000 | C6: 4 | D6: =B6*C6 -> 180000
A7: Total | D7: =SUM(D4:D6) -> 520000
A11: GESTION DE RIESGOS | C11: =OTROS!$C$24/PRECIO -> 0.11232245
A12: DESCRIPCIÓN | B12: % | C12: MONTO M$
A13: Fondo de Reserva | B13: =OTROS!$C13/PRECIO -> 0.032671193 | C13: 1000000 | E13: <- monto de dinero que separo para cumplir contingencias
A14: Plan de Tratamientos de Riesgos | B14: =OTROS!$C14/PRECIO -> 0.079651257 | C14: =SUM(C15:C23) -> 2437966
A15: Plan de Tratamiento Cro-001 - Descomponer tareas complejas y revisar estimaciones semanalmente. | B15: =OTROS!$C15/PRECIO -> 0.0096134331 | C15: 294248 | E15: <- planes de tratamiento de los riesgos críticos
A16: Plan de Tratamiento Cro-002 - Implementar control formal de cambios y aprobación previa. | B16: =OTROS!$C16/PRECIO -> 0.012251697 | C16: 375000
A17: Plan de Tratamiento Ges-001- Revisar estimaciones con el equipo antes de aprobar el cronograma. | B17: =OTROS!$C17/PRECIO -> 0.0028840169 | C17: 88274
A18: Plan de Tratamiento Ges-003- Congelar alcance por iteraciones y formalizar solicitudes de cambio. | B18: =OTROS!$C18/PRECIO -> 0.017304199 | C18: 529647
A19: Plan de Tratamiento Cal-001- Realizar pruebas periódicas de integración entre módulos. | B19: =OTROS!$C19/PRECIO -> 0.0026136954 | C19: 80000
A20: Plan de Tratamiento Cal-003-Definir guía básica de codificación y revisión entre pares. | B20: =OTROS!$C20/PRECIO -> 0.0073510184 | C20: 225000
A21: Plan de Tratamiento Cro-003 - Agregar holgura del 10% a actividades críticas. | B21: =OTROS!$C21/PRECIO -> 0.0057680664 | C21: 176549
A22: Plan de Tratamiento Cro-005 - Revisiones tempranas de entregables y validación continua. | B22: =OTROS!$C22/PRECIO -> 0.012251697 | C22: 375000
A23: Plan de Tratamiento Cro-006 - Mantener prácticas de testing y adelantar despliegues cuando sea posible. | B23: =OTROS!$C23/PRECIO -> 0.0096134331 | C23: 294248
A24: Total | C24: =C13+C14 -> 3437966
A28: UTILIDAD | C28: =OTROS!$C$31/PRECIO -> 0.25
A29: DESCRIPCION | B29: % | C29: MONTO M$
A30: UTILIDAD | B30: 0.25 | C30: =OTROS!$B30*PRECIO -> 7652001
A31: TOTAL | C31: =SUBTOTAL(109,OTROS!$C$30) -> 7652001

Sheet TOTAL
A1: COSTO TOTAL DEL PROYECTO
F2: 760 UF
A3: PRECIO | B3: =PRECIO/PRECIO -> 1 | F3: 30608004 | H3: Rangos aceptables | J3: <- monto que el colegio está dispuesto a pagar
A4: UTILIDAD | B4: =F4/PRECIO -> 0.25 | F4: =OTROS!$C$31 -> 7652001 | H4: 20-30% | J4: <- utilidad que elegimos
A5: PRESUPUESTO | B5: =F5/PRECIO -> #VALUE! | C5: HONORARIOS, INCENTIVOS, REMUNERACIONES | D5: =E5/PRECIO -> #VALUE! | E5: =REMUNERACIONES!G13 -> #VALUE! | F5: =SUM(E5:E10) -> #VALUE! | H5: ="65-75%" -> 65-75%
C6: EQUIPOS | D6: =E6/PRECIO -> #REF! | E6: ='EQUIPOS E INFRAESTRUCTURA'!F9 -> #REF!
C7: INFRAESTRUCTURA | D7: =E7/PRECIO -> #REF! | E7: ='EQUIPOS E INFRAESTRUCTURA'!F18 -> #REF!
C8: SOFTWARE | D8: =E8/PRECIO -> #REF! | E8: ='SOFTWARE Y FUNGIBLES'!E7 -> #REF!
C9: FUNGIBLES | D9: =E9/PRECIO -> 0.0032671193 | E9: ='SOFTWARE Y FUNGIBLES'!D14 -> 100000
C10: GASTOS COMUNES | D10: =E10/PRECIO -> 0.01698902 | E10: =OTROS!D7 -> 520000
A11: RIESGOS | B11: =F11/PRECIO -> 0.11232245 | C11: PLANES DE TRATAMIENTO | D11: =E11/PRECIO -> 0.079651257 | E11: =OTROS!C14 -> 2437966 | F11: =SUM(E11:E12) -> 3437966 | H11: ="5%" -> 5%
C12: FONDO RESERVA | D12: =E12/PRECIO -> 0.032671193 | E12: =OTROS!C13 -> 1000000
A13: Total Estipulado | B13: =SUM(B4:B12) -> #VALUE! | E13: Total Costo | F13: =SUM(F4:F12) -> #VALUE!
